Workbook

Sheet Dashboard
B1: TABLEAU DE BORD — ANALYSE DES VENTES 2023-2024 | S1: Catégorie | T1: CA (€) | V1: Mois | W1: CA 2023 (€) | X1: CA Cumulé 2023 (€)
B2: 200 transactions | 5 vendeurs | 4 catégories | 5 régions | S2: Informatique | T2: =SUMIF(Ventes!E$2:E$201,"Informatique",Ventes!I$2:I$201) -> 298630.9 | V2: Jan | W2: 48824 | X2: 48824
S3: Téléphonie | T3: =SUMIF(Ventes!E$2:E$201,"Téléphonie",Ventes!I$2:I$201) -> 151093.7 | V3: Fév | W3: 26931 | X3: 75755
S4: Accessoires | T4: =SUMIF(Ventes!E$2:E$201,"Accessoires",Ventes!I$2:I$201) -> 0 | V4: Mar | W4: 26719 | X4: 102474
B5: CA TOTAL LIVRÉ | F5: COMMANDES LIVRÉES | J5: MARGE MOYENNE (%) | N5: TAUX D'ANNULATION | S5: Logiciels | T5: =SUMIF(Ventes!E$2:E$201,"Logiciels",Ventes!I$2:I$201) -> 0 | V5: Avr | W5: 41781 | X5: 144255
B6: =SUMIF(Ventes!L2:L201,"Livré",Ventes!I2:I201) -> 322336.3 | F6: =COUNTIF(Ventes!L2:L201,"Livré") -> 145 | J6: =AVERAGEIF(Ventes!L2:L201,"Livré",Ventes!K2:K201) -> 30.2 | N6: =COUNTIF(Ventes!L2:L201,"Annulé")/COUNTA(Ventes!B2:B201)*100 -> 13.5 | V6: Mai | W6: 42511 | X6: 186766
V7: Jun | W7: 42919 | X7: 229685
S8: Vendeur | T8: CA (€) | V8: Jul | W8: 54399 | X8: 284084
B9: sur 200 transactions | F9: sur 200 transactions | J9: sur 200 transactions | N9: sur 200 transactions | S9: Alice Martin | T9: =SUMIF(Ventes!C$2:C$201,"Alice Martin",Ventes!I$2:I$201) -> 171973.65 | V9: Aoû | W9: 34120 | X9: 318204
S10: Bruno Lefèvre | T10: =SUMIF(Ventes!C$2:C$201,"Bruno Lefèvre",Ventes!I$2:I$201) -> 195732.05 | V10: Sep | W10: 32751 | X10: 350955
B11: CA PAR CATÉGORIE | I11: PERFORMANCE DES VENDEURS | S11: Camille Dubois | T11: =SUMIF(Ventes!C$2:C$201,"Camille Dubois",Ventes!I$2:I$201) -> 82018.9 | V11: Oct | W11: 39154 | X11: 390109
S12: David Moreau | T12: =SUMIF(Ventes!C$2:C$201,"David Moreau",Ventes!I$2:I$201) -> 0 | V12: Nov | W12: 35137 | X12: 425246
S13: Emma Bernard | T13: =SUMIF(Ventes!C$2:C$201,"Emma Bernard",Ventes!I$2:I$201) -> 0 | V13: Déc | W13: 24477 | X13: 449723
S15: Région | T15: CA (€) | V15: Canal | W15: CA (€)
S16: Île-de-France | T16: =SUMIF(Ventes!D$2:D$201,"Île-de-France",Ventes!I$2:I$201) -> 184438.1 | V16: E-commerce | W16: 211556
S17: Auvergne-Rhône-Alpes | T17: =SUMIF(Ventes!D$2:D$201,"Auvergne-Rhône-Alpes",Ventes!I$2:I$201) -> 176913.1 | V17: Boutique | W17: 238169
S18: Nouvelle-Aquitaine | T18: =SUMIF(Ventes!D$2:D$201,"Nouvelle-Aquitaine",Ventes!I$2:I$201) -> 88373.4
S19: Occitanie | T19: =SUMIF(Ventes!D$2:D$201,"Occitanie",Ventes!I$2:I$201) -> 0
S20: Bretagne | T20: =SUMIF(Ventes!D$2:D$201,"Bretagne",Ventes!I$2:I$201) -> 0
S22: Statut | T22: Nb
S23: Livré | T23: =COUNTIF(Ventes!L$2:L$201,"Livré") -> 145
S24: En cours | T24: =COUNTIF(Ventes!L$2:L$201,"En cours") -> 28
S25: Annulé | T25: =COUNTIF(Ventes!L$2:L$201,"Annulé") -> 27
B27: CA PAR RÉGION | I27: RÉPARTITION : STATUT & CANAL | S27: Canal | T27: CA (€)
S28: E-commerce | T28: =SUMIF(Ventes!M$2:M$201,"E-commerce",Ventes!I$2:I$201) -> 211555.85
S29: Boutique | T29: =SUMIF(Ventes!M$2:M$201,"Boutique",Ventes!I$2:I$201) -> 238168.75
S30: Téléphone | T30: =SUMIF(Ventes!M$2:M$201,"Téléphone",Ventes!I$2:I$201) -> 0
S31: Revendeur | T31: =SUMIF(Ventes!M$2:M$201,"Revendeur",Ventes!I$2:I$201) -> 0
B46: 📅 ÉVOLUTION DU CA MENSUEL | I46: 🛒 CA PAR CANAL DE VENTE

Sheet Ventes
A1: Date | B1: ID Commande | C1: Vendeur | D1: Région | E1: Catégorie | F1: Produit | G1: Quantité | H1: Prix Unitaire (€) | I1: CA (€) | J1: Remise (%) | K1: Marge (%) | L1: Statut | M1: Canal de Vente
A2: 19/01/2023 | B2: CMD-0001 | C2: Camille Dubois | D2: Île-de-France | E2: Téléphonie | F2: Smartphone X12 | G2: 5 | H2: 799 | I2: 3995 | J2: 0 | K2: 32.5 | L2: Livré | M2: E-commerce
A3: 22/10/2023 | B3: CMD-0002 | C3: Alice Martin | D3: Île-de-France | E3: Informatique | F3: Laptop Pro 15 | G3: 5 | H3: 1299 | I3: 6495 | J3: 0 | K3: 27.8 | L3: Livré | M3: E-commerce
A4: 45176 | B4: CMD-0003 | C4: Alice Martin | D4: Île-de-France | E4: Informatique | F4: Laptop Pro 15 | G4: 5 | H4: 1299 | I4: 6495 | J4: 0 | K4: 34 | L4: Livré | M4: E-commerce
A5: 45051 | B5: CMD-0004 | C5: Alice Martin | D5: Auvergne-Rhône-Alpes | E5: Informatique | F5: Tablette HD | G5: 1 | H5: 449 | I5: 449 | J5: 0 | K5: 34.3 | L5: Livré | M5: Boutique
A6: 25/11/2023 | B6: CMD-0005 | C6: Alice Martin | D6: Île-de-France | E6: Téléphonie | F6: Smartphone Y8 | G6: 3 | H6: 499 | I6: 1497 | J6: 0 | K6: 25.2 | L6: Livré | M6: Boutique
A7: 45113 | B7: CMD-0006 | C7: Bruno Lefèvre | D7: Île-de-France | E7: Informatique | F7: Laptop Air 13 | G7: 5 | H7: 899 | I7: 4495 | J7: 0 | K7: 32.8 | L7: Livré | M7: Boutique
A8: 44937 | B8: CMD-0007 | C8: Bruno Lefèvre | D8: Auvergne-Rhône-Alpes | E8: Téléphonie | F8: Smartphone X12 | G8: 1 | H8: 799 | I8: 799 | J8: 0 | K8: 27.6 | L8: Livré | M8: E-commerce
A9: 31/07/2023 | B9: CMD-0008 | C9: Bruno Lefèvre | D9: Île-de-France | E9: Informatique | F9: Laptop Pro 15 | G9: 1 | H9: 1299 | I9: 1299 | J9: 0 | K9: 33.7 | L9: En cours | M9: Boutique
A10: 44991 | B10: CMD-0009 | C10: Bruno Lefèvre | D10: Auvergne-Rhône-Alpes | E10: Informatique | F10: Laptop Air 13 | G10: 4 | H10: 899 | I10: 3596 | J10: 0 | K10: 34.8 | L10: Livré | M10: E-commerce
A11: 44989 | B11: CMD-0010 | C11: Camille Dubois | D11: Auvergne-Rhône-Alpes | E11: Informatique | F11: Laptop Air 13 | G11: 2 | H11: 899 | I11: 1708.1 | J11: 5 | K11: 28.1 | L11: Livré | M11: E-commerce
A12: 45143 | B12: CMD-0011 | C12: Alice Martin | D12: Auvergne-Rhône-Alpes | E12: Téléphonie | F12: Smartphone Y8 | G12: 5 | H12: 499 | I12: 2495 | J12: 0 | K12: 26.5 | L12: Livré | M12: E-commerce
A13: 25/05/2023 | B13: CMD-0012 | C13: Bruno Lefèvre | D13: Nouvelle-Aquitaine | E13: Téléphonie | F13: Smartphone Y8 | G13: 5 | H13: 499 | I13: 2495 | J13: 0 | K13: 26.7 | L13: Livré | M13: Boutique
A14: 45084 | B14: CMD-0013 | C14: Camille Dubois | D14: Auvergne-Rhône-Alpes | E14: Téléphonie | F14: Smartphone X12 | G14: 4 | H14: 799 | I14: 3196 | J14: 0 | K14: 34.5 | L14: Annulé | M14: Boutique
A15: 21/06/2023 | B15: CMD-0014 | C15: Alice Martin | D15: Île-de-France | E15: Téléphonie | F15: Smartphone Y8 | G15: 4 | H15: 499 | I15: 1896.2 | J15: 5 | K15: 26.3 | L15: Livré | M15: Boutique
A16: 45018 | B16: CMD-0015 | C16: Alice Martin | D16: Auvergne-Rhône-Alpes | E16: Informatique | F16: Laptop Pro 15 | G16: 3 | H16: 1299 | I16: 3702.15 | J16: 5 | K16: 35 | L16: En cours | M16: E-commerce
A17: 44969 | B17: CMD-0016 | C17: Bruno Lefèvre | D17: Île-de-France | E17: Téléphonie | F17: Écouteurs Sans Fil | G17: 4 | H17: 179 | I17: 716 | J17: 0 | K17: 31.8 | L17: En cours | M17: E-commerce
A18: 45084 | B18: CMD-0017 | C18: Bruno Lefèvre | D18: Nouvelle-Aquitaine | E18: Téléphonie | F18: Smartphone Y8 | G18: 4 | H18: 499 | I18: 1996 | J18: 0 | K18: 34.4 | L18: Livré | M18: E-commerce
A19: 44986 | B19: CMD-0018 | C19: Alice Martin | D19: Auvergne-Rhône-Alpes | E19: Informatique | F19: Laptop Air 13 | G19: 1 | H19: 899 | I19: 899 | J19: 0 | K19: 34.3 | L19: Livré | M19: E-commerce
A20: 18/01/2023 | B20: CMD-0019 | C20: Alice Martin | D20: Nouvelle-Aquitaine | E20: Informatique | F20: Tablette HD | G20: 4 | H20: 449 | I20: 1796 | J20: 0 | K20: 30.1 | L20: Livré | M20: Boutique
A21: 20/02/2023 | B21: CMD-0020 | C21: Alice Martin | D21: Île-de-France | E21: Téléphonie | F21: Écouteurs Sans Fil | G21: 1 | H21: 179 | I21: 170.05 | J21: 5 | K21: 33.2 | L21: Livré | M21: Boutique
A22: 21/10/2023 | B22: CMD-0021 | C22: Bruno Lefèvre | D22: Auvergne-Rhône-Alpes | E22: Téléphonie | F22: Écouteurs Sans Fil | G22: 5 | H22: 179 | I22: 895 | J22: 0 | K22: 31.6 | L22: Livré | M22: Boutique
A23: 27/10/2023 | B23: CMD-0022 | C23: Bruno Lefèvre | D23: Île-de-France | E23: Informatique | F23: Laptop Pro 15 | G23: 5 | H23: 1299 | I23: 6495 | J23: 0 | K23: 30 | L23: Livré | M23: E-commerce
A24: 45112 | B24: CMD-0023 | C24: Bruno Lefèvre | D24: Auvergne-Rhône-Alpes | E24: Informatique | F24: Laptop Air 13 | G24: 5 | H24: 899 | I24: 4495 | J24: 0 | K24: 32.1 | L24: Livré | M24: Boutique
A25: 19/07/2023 | B25: CMD-0024 | C25: Alice Martin | D25: Île-de-France | E25: Téléphonie | F25: Smartphone Y8 | G25: 5 | H25: 499 | I25: 2495 | J25: 0 | K25: 31.3 | L25: Livré | M25: E-commerce
A26: 45108 | B26: CMD-0025 | C26: Camille Dubois | D26: Île-de-France | E26: Informatique | F26: Laptop Pro 15 | G26: 5 | H26: 1299 | I26: 6170.25 | J26: 5 | K26: 31 | L26: Annulé | M26: E-commerce
A27: 28/03/2023 | B27: CMD-0026 | C27: Camille Dubois | D27: Nouvelle-Aquitaine | E27: Informatique | F27: Laptop Air 13 | G27: 1 | H27: 899 | I27: 899 | J27: 0 | K27: 32.9 | L27: Livré | M27: E-commerce
A28: 28/03/2023 | B28: CMD-0027 | C28: Bruno Lefèvre | D28: Auvergne-Rhône-Alpes | E28: Informatique | F28: Laptop Pro 15 | G28: 2 | H28: 1299 | I28: 2598 | J28: 0 | K28: 29.7 | L28: Livré | M28: E-commerce
A29: 45026 | B29: CMD-0028 | C29: Camille Dubois | D29: Île-de-France | E29: Informatique | F29: Laptop Pro 15 | G29: 1 | H29: 1299 | I29: 1299 | J29: 0 | K29: 26.4 | L29: Annulé | M29: E-commerce
A30: 23/10/2023 | B30: CMD-0029 | C30: Bruno Lefèvre | D30: Île-de-France | E30: Informatique | F30: Tablette HD | G30: 3 | H30: 449 | I30: 1347 | J30: 0 | K30: 35 | L30: Livré | M30: Boutique
A31: 45141 | B31: CMD-0030 | C31: Alice Martin | D31: Île-de-France | E31: Informatique | F31: Laptop Air 13 | G31: 4 | H31: 899 | I31: 3596 | J31: 0 | K31: 29.6 | L31: Livré | M31: Boutique
A32: 24/11/2023 | B32: CMD-0031 | C32: Camille Dubois | D32: Auvergne-Rhône-Alpes | E32: Téléphonie | F32: Smartphone X12 | G32: 2 | H32: 799 | I32: 1598 | J32: 0 | K32: 30.2 | L32: En cours | M32: Boutique
A33: 45234 | B33: CMD-0032 | C33: Alice Martin | D33: Auvergne-Rhône-Alpes | E33: Téléphonie | F33: Smartphone Y8 | G33: 1 | H33: 499 | I33: 499 | J33: 0 | K33: 26 | L33: Livré | M33: Boutique
A34: 15/11/2023 | B34: CMD-0033 | C34: Alice Martin | D34: Île-de-France | E34: Informatique | F34: Laptop Pro 15 | G34: 5 | H34: 1299 | I34: 6495 | J34: 0 | K34: 29.3 | L34: Livré | M34: Boutique
A35: 45207 | B35: CMD-0034 | C35: Alice Martin | D35: Île-de-France | E35: Informatique | F35: Laptop Air 13 | G35: 3 | H35: 899 | I35: 2697 | J35: 0 | K35: 27.8 | L35: En cours | M35: E-commerce
A36: 25/06/2023 | B36: CMD-0035 | C36: Camille Dubois | D36: Nouvelle-Aquitaine | E36: Informatique | F36: Laptop Air 13 | G36: 2 | H36: 899 | I36: 1708.1 | J36: 5 | K36: 25.4 | L36: Annulé | M36: Boutique
A37: 21/06/2023 | B37: CMD-0036 | C37: Bruno Lefèvre | D37: Île-de-France | E37: Informatique | F37: Laptop Pro 15 | G37: 5 | H37: 1299 | I37: 6495 | J37: 0 | K37: 25.1 | L37: Livré | M37: Boutique
A38: 44927 | B38: CMD-0037 | C38: Bruno Lefèvre | D38: Auvergne-Rhône-Alpes | E38: Téléphonie | F38: Smartphone X12 | G38: 1 | H38: 799 | I38: 799 | J38: 0 | K38: 32 | L38: En cours | M38: E-commerce
A39: 17/09/2023 | B39: CMD-0038 | C39: Bruno Lefèvre | D39: Nouvelle-Aquitaine | E39: Téléphonie | F39: Smartphone X12 | G39: 1 | H39: 799 | I39: 799 | J39: 0 | K39: 27.6 | L39: Livré | M39: E-commerce
A40: 45205 | B40: CMD-0039 | C40: Alice Martin | D40: Île-de-France | E40: Informatique | F40: Laptop Pro 15 | G40: 4 | H40: 1299 | I40: 4936.2 | J40: 5 | K40: 30.5 | L40: En cours | M40: E-commerce
...

Sheet Guide
A1: 🗂️ BASE DE DONNÉES — GUIDE D'UTILISATION
A3: 📋 STRUCTURE DE LA BASE
A4: Colonne | B4: Type | C4: Description
A5: Date | B5: Texte (JJ/MM/AAAA) | C5: Date de la commande
A6: ID Commande | B6: Texte | C6: Identifiant unique CMD-XXXX
A7: Vendeur | B7: Texte | C7: Nom du commercial
A8: Région | B8: Texte | C8: Région de vente (France)
A9: Catégorie | B9: Texte | C9: Catégorie de produit
A10: Produit | B10: Texte | C10: Nom du produit
A11: Quantité | B11: Entier | C11: Nombre d'unités vendues
A12: Prix Unitaire (€) | B12: Décimal | C12: Prix catalogue unitaire
A13: CA (€) | B13: Décimal | C13: Chiffre d'affaires (après remise)
A14: Remise (%) | B14: Entier | C14: Remise appliquée (0, 5, 10, 15, 20%)
A15: Marge (%) | B15: Décimal | C15: Taux de marge brute
... A17: Canal de Vente | B17: Texte | C17: E-commerce / Boutique / Téléphone / Revendeur
A19: 💡 IDÉES DE TABLEAUX DE BORD
A20: Analyse | B20: Mesure | C20: Dimension
A21: CA par mois | B21: SOMME(CA) | C21: Date → Mois
A22: CA par région | B22: SOMME(CA) | C22: Région
A23: Performance vendeurs | B23: SOMME(CA) / NB commandes | C23: Vendeur
A24: Top produits | B24: SOMME(Quantité) / SOMME(CA) | C24: Produit
A25: Répartition par canal | B25: NB commandes / % | C25: Canal de Vente
A26: Évolution marge | B26: MOYENNE(Marge) | C26: Date → Trimestre
A27: Taux d'annulation | B27: NB(Annulé)/Total | C27: Statut
A28: Remise vs Marge | B28: Corrélation | C28: Remise / Marge
